Workbook
Name AssetIDs: 'MASTER DATA'!$A$5:$A$12
Name Technicians: 'MASTER DATA'!$J$5:$J$8

Sheet START HERE
A1: CONTOH PERBAIKAN WORKBOOK
A2: Contoh ini dibuat ulang dari pengalaman sebelumnya. Semua nama dan data pengukuran bersifat fiktif.
A4: Yang diperlihatkan dalam contoh ini
A5: Teknisi mengisi data di satu sheet. Informasi alat diambil dari MASTER DATA, lalu workbook menghitung hasil dan memperbarui laporan. Reviewer tetap dapat mengikuti angka yang dipakai dalam perhitungan.
A8: Alur workbook
A10: 1 INPUT LOG Diisi oleh teknisi | D10: 2 MASTER DATA Referensi alat | G10: 3 CALCULATION Rincian hitung | I10: 4 REPORT Ringkasan hasil
C11: → | F11: →
A15: Cara menggunakan
A16: 1. Buka INPUT LOG. Teknisi hanya perlu mengisi sel berwarna kuning.
A17: 2. Pilih Asset ID dan nama teknisi dari daftar yang tersedia.
A18: 3. Isi tiga hasil pengukuran. Workbook akan menghitung rata-rata, selisih, dan status.
A19: 4. Buka REPORT untuk melihat rekap. Hasil kasus acuan ada di VALIDATION.
A20: 5. File demo tidak dikunci agar rumus dapat diperiksa. Proteksi dapat diaktifkan saat masuk tahap UAT.
A23: Legenda
A24: Input pengguna | D24: Hasil perhitungan | G24: Data referensi | I24: Perlu perhatian

Sheet MASTER DATA
A1: MASTER DATA
A2: Daftar alat dan nilai acuan. Hanya pengelola data yang boleh mengubah sheet ini.
A4: Asset ID | B4: Nama alat | C4: Lokasi | D4: Unit | E4: Nilai acuan | F4: Toleransi +/- | G4: Aktif | H4: Penanggung jawab | J4: Teknisi
A5: AST-001 | B5: Pressure Gauge 0 to 10 bar | C5: Workshop A | D5: bar | E5: 5 | F5: 0.1 | G5: Yes | H5: Engineering | J5: Ayu Pratama
A6: AST-002 | B6: Temperature Sensor | C6: Line 1 | D6: deg C | E6: 100 | F6: 0.5 | G6: Yes | H6: Engineering | J6: Bima Santoso
A7: AST-003 | B7: Flow Meter | C7: Utility Area | D7: L/min | E7: 50 | F7: 1 | G7: Yes | H7: Maintenance | J7: Citra Lestari
A8: AST-004 | B8: Digital Caliper | C8: QC Laboratory | D8: mm | E8: 25 | F8: 0.05 | G8: Yes | H8: Quality | J8: Danu Wijaya
A9: AST-005 | B9: Torque Wrench | C9: Assembly | D9: N m | E9: 80 | F9: 2 | G9: Yes | H9: Quality
A10: AST-006 | B10: Weighing Scale | C10: Warehouse | D10: kg | E10: 10 | F10: 0.02 | G10: Yes | H10: Operations
A11: AST-007 | B11: Humidity Sensor | C11: Storage Room | D11: %RH | E11: 60 | F11: 2 | G11: Yes | H11: Engineering
A12: AST-008 | B12: Voltage Meter | C12: Electrical Shop | D12: V | E12: 220 | F12: 1 | G12: Yes | H12: Electrical

Sheet INPUT LOG
A1: CATATAN PEMERIKSAAN TEKNISI
A2: Isi sel berwarna kuning. Sel biru berisi rumus. Proteksi sengaja dimatikan pada file demo.
A4: Work Order | B4: Tanggal | C4: Teknisi | D4: Asset ID | E4: Nama alat | F4: Lokasi | G4: Unit | H4: Nilai acuan | I4: Toleransi +/- | J4: Pengukuran 1 | K4: Pengukuran 2 | L4: Pengukuran 3 | M4: Rata-rata | N4: Selisih | O4: Status | P4: Catatan
A5: WO-2401 | B5: 46286 | C5: Ayu Pratama | D5: AST-001 | E5: =IF($D5="","",IFERROR(INDEX('MASTER DATA'!$B$5:$B$12,MATCH($D5,'MASTER DATA'!$A$5:$A$12,0)),"NOT FOUND")) -> Pressure Gauge 0 to 10 bar | F5: =IF($D5="","",IFERROR(INDEX('MASTER DATA'!$C$5:$C$12,MATCH($D5,'MASTER DATA'!$A$5:$A$12,0)),"NOT FOUND")) -> Workshop A | G5: =IF($D5="","",IFERROR(INDEX('MASTER DATA'!$D$5:$D$12,MATCH($D5,'MASTER DATA'!$A$5:$A$12,0)),"")) -> bar | H5: =IF($D5="","",IFERROR(INDEX('MASTER DATA'!$E$5:$E$12,MATCH($D5,'MASTER DATA'!$A$5:$A$12,0)),"")) -> 5 | I5: =IF($D5="","",IFERROR(INDEX('MASTER DATA'!$F$5:$F$12,MATCH($D5,'MASTER DATA'!$A$5:$A$12,0)),"")) -> 0.1 | J5: 5.02 | K5: 5.01 | L5: 5.03 | M5: =IF(COUNT($J5:$L5)<3,"",AVERAGE($J5:$L5)) -> 5.02 | N5: =IF($M5="","",$M5-$H5) -> 0.02 | O5: =IF(OR($A5="",$B5="",$C5="",$D5="",COUNT($J5:$L5)<3),"INCOMPLETE",IF(ABS($N5)<=$I5,"PASS","REVIEW")) -> PASS | P5: Pemeriksaan rutin
A6: WO-2402 | B6: 46287 | C6: Bima Santoso | D6: AST-002 | E6: =IF($D6="","",IFERROR(INDEX('MASTER DATA'!$B$5:$B$12,MATCH($D6,'MASTER DATA'!$A$5:$A$12,0)),"NOT FOUND")) -> Temperature Sensor | F6: =IF($D6="","",IFERROR(INDEX('MASTER DATA'!$C$5:$C$12,MATCH($D6,'MASTER DATA'!$A$5:$A$12,0)),"NOT FOUND")) -> Line 1 | G6: =IF($D6="","",IFERROR(INDEX('MASTER DATA'!$D$5:$D$12,MATCH($D6,'MASTER DATA'!$A$5:$A$12,0)),"")) -> deg C | H6: =IF($D6="","",IFERROR(INDEX('MASTER DATA'!$E$5:$E$12,MATCH($D6,'MASTER DATA'!$A$5:$A$12,0)),"")) -> 100 | I6: =IF($D6="","",IFERROR(INDEX('MASTER DATA'!$F$5:$F$12,MATCH($D6,'MASTER DATA'!$A$5:$A$12,0)),"")) -> 0.5 | J6: 100.2 | K6: 100.1 | L6: 100.3 | M6: =IF(COUNT($J6:$L6)<3,"",AVERAGE($J6:$L6)) -> 100.2 | N6: =IF($M6="","",$M6-$H6) -> 0.2 | O6: =IF(OR($A6="",$B6="",$C6="",$D6="",COUNT($J6:$L6)<3),"INCOMPLETE",IF(ABS($N6)<=$I6,"PASS","REVIEW")) -> PASS | P6: Pemeriksaan rutin
A7: WO-2403 | B7: 46288 | C7: Citra Lestari | D7: AST-003 | E7: =IF($D7="","",IFERROR(INDEX('MASTER DATA'!$B$5:$B$12,MATCH($D7,'MASTER DATA'!$A$5:$A$12,0)),"NOT FOUND")) -> Flow Meter | F7: =IF($D7="","",IFERROR(INDEX('MASTER DATA'!$C$5:$C$12,MATCH($D7,'MASTER DATA'!$A$5:$A$12,0)),"NOT FOUND")) -> Utility Area | G7: =IF($D7="","",IFERROR(INDEX('MASTER DATA'!$D$5:$D$12,MATCH($D7,'MASTER DATA'!$A$5:$A$12,0)),"")) -> L/min | H7: =IF($D7="","",IFERROR(INDEX('MASTER DATA'!$E$5:$E$12,MATCH($D7,'MASTER DATA'!$A$5:$A$12,0)),"")) -> 50 | I7: =IF($D7="","",IFERROR(INDEX('MASTER DATA'!$F$5:$F$12,MATCH($D7,'MASTER DATA'!$A$5:$A$12,0)),"")) -> 1 | J7: 51.2 | K7: 51.1 | L7: 51 | M7: =IF(COUNT($J7:$L7)<3,"",AVERAGE($J7:$L7)) -> 51.1 | N7: =IF($M7="","",$M7-$H7) -> 1.1 | O7: =IF(OR($A7="",$B7="",$C7="",$D7="",COUNT($J7:$L7)<3),"INCOMPLETE",IF(ABS($N7)<=$I7,"PASS","REVIEW")) -> REVIEW | P7: Periksa penyimpangan
A8: WO-2404 | B8: 46289 | C8: Danu Wijaya | D8: AST-004 | E8: =IF($D8="","",IFERROR(INDEX('MASTER DATA'!$B$5:$B$12,MATCH($D8,'MASTER DATA'!$A$5:$A$12,0)),"NOT FOUND")) -> Digital Caliper | F8: =IF($D8="","",IFERROR(INDEX('MASTER DATA'!$C$5:$C$12,MATCH($D8,'MASTER DATA'!$A$5:$A$12,0)),"NOT FOUND")) -> QC Laboratory | G8: =IF($D8="","",IFERROR(INDEX('MASTER DATA'!$D$5:$D$12,MATCH($D8,'MASTER DATA'!$A$5:$A$12,0)),"")) -> mm | H8: =IF($D8="","",IFERROR(INDEX('MASTER DATA'!$E$5:$E$12,MATCH($D8,'MASTER DATA'!$A$5:$A$12,0)),"")) -> 25 | I8: =IF($D8="","",IFERROR(INDEX('MASTER DATA'!$F$5:$F$12,MATCH($D8,'MASTER DATA'!$A$5:$A$12,0)),"")) -> 0.05 | J8: 25.01 | K8: 25.02 | L8: 25.01 | M8: =IF(COUNT($J8:$L8)<3,"",AVERAGE($J8:$L8)) -> 25.013333 | N8: =IF($M8="","",$M8-$H8) -> 0.013333333 | O8: =IF(OR($A8="",$B8="",$C8="",$D8="",COUNT($J8:$L8)<3),"INCOMPLETE",IF(ABS($N8)<=$I8,"PASS","REVIEW")) -> PASS | P8: Pemeriksaan rutin
A9: WO-2405 | B9: 46290 | C9: Ayu Pratama | D9: AST-006 | E9: =IF($D9="","",IFERROR(INDEX('MASTER DATA'!$B$5:$B$12,MATCH($D9,'MASTER DATA'!$A$5:$A$12,0)),"NOT FOUND")) -> Weighing Scale | F9: =IF($D9="","",IFERROR(INDEX('MASTER DATA'!$C$5:$C$12,MATCH($D9,'MASTER DATA'!$A$5:$A$12,0)),"NOT FOUND")) -> Warehouse | G9: =IF($D9="","",IFERROR(INDEX('MASTER DATA'!$D$5:$D$12,MATCH($D9,'MASTER DATA'!$A$5:$A$12,0)),"")) -> kg | H9: =IF($D9="","",IFERROR(INDEX('MASTER DATA'!$E$5:$E$12,MATCH($D9,'MASTER DATA'!$A$5:$A$12,0)),"")) -> 10 | I9: =IF($D9="","",IFERROR(INDEX('MASTER DATA'!$F$5:$F$12,MATCH($D9,'MASTER DATA'!$A$5:$A$12,0)),"")) -> 0.02 | J9: 10.03 | K9: 10.04 | L9: 10.03 | M9: =IF(COUNT($J9:$L9)<3,"",AVERAGE($J9:$L9)) -> 10.033333 | N9: =IF($M9="","",$M9-$H9) -> 0.033333333 | O9: =IF(OR($A9="",$B9="",$C9="",$D9="",COUNT($J9:$L9)<3),"INCOMPLETE",IF(ABS($N9)<=$I9,"PASS","REVIEW")) -> REVIEW | P9: Perlu diperiksa ulang
E10: =IF($D10="","",IFERROR(INDEX('MASTER DATA'!$B$5:$B$12,MATCH($D10,'MASTER DATA'!$A$5:$A$12,0)),"NOT FOUND")) | F10: =IF($D10="","",IFERROR(INDEX('MASTER DATA'!$C$5:$C$12,MATCH($D10,'MASTER DATA'!$A$5:$A$12,0)),"NOT FOUND")) | G10: =IF($D10="","",IFERROR(INDEX('MASTER DATA'!$D$5:$D$12,MATCH($D10,'MASTER DATA'!$A$5:$A$12,0)),"")) | H10: =IF($D10="","",IFERROR(INDEX('MASTER DATA'!$E$5:$E$12,MATCH($D10,'MASTER DATA'!$A$5:$A$12,0)),"")) | I10: =IF($D10="","",IFERROR(INDEX('MASTER DATA'!$F$5:$F$12,MATCH($D10,'MASTER DATA'!$A$5:$A$12,0)),"")) | M10: =IF(COUNT($J10:$L10)<3,"",AVERAGE($J10:$L10)) | N10: =IF($M10="","",$M10-$H10) | O10: =IF(OR($A10="",$B10="",$C10="",$D10="",COUNT($J10:$L10)<3),"INCOMPLETE",IF(ABS($N10)<=$I10,"PASS","REVIEW")) -> INCOMPLETE
E11: =IF($D11="","",IFERROR(INDEX('MASTER DATA'!$B$5:$B$12,MATCH($D11,'MASTER DATA'!$A$5:$A$12,0)),"NOT FOUND")) | F11: =IF($D11="","",IFERROR(INDEX('MASTER DATA'!$C$5:$C$12,MATCH($D11,'MASTER DATA'!$A$5:$A$12,0)),"NOT FOUND")) | G11: =IF($D11="","",IFERROR(INDEX('MASTER DATA'!$D$5:$D$12,MATCH($D11,'MASTER DATA'!$A$5:$A$12,0)),"")) | H11: =IF($D11="","",IFERROR(INDEX('MASTER DATA'!$E$5:$E$12,MATCH($D11,'MASTER DATA'!$A$5:$A$12,0)),"")) | I11: =IF($D11="","",IFERROR(INDEX('MASTER DATA'!$F$5:$F$12,MATCH($D11,'MASTER DATA'!$A$5:$A$12,0)),"")) | M11: =IF(COUNT($J11:$L11)<3,"",AVERAGE($J11:$L11)) | N11: =IF($M11="","",$M11-$H11) | O11: =IF(OR($A11="",$B11="",$C11="",$D11="",COUNT($J11:$L11)<3),"INCOMPLETE",IF(ABS($N11)<=$I11,"PASS","REVIEW")) -> INCOMPLETE
E12: =IF($D12="","",IFERROR(INDEX('MASTER DATA'!$B$5:$B$12,MATCH($D12,'MASTER DATA'!$A$5:$A$12,0)),"NOT FOUND")) | F12: =IF($D12="","",IFERROR(INDEX('MASTER DATA'!$C$5:$C$12,MATCH($D12,'MASTER DATA'!$A$5:$A$12,0)),"NOT FOUND")) | G12: =IF($D12="","",IFERROR(INDEX('MASTER DATA'!$D$5:$D$12,MATCH($D12,'MASTER DATA'!$A$5:$A$12,0)),"")) | H12: =IF($D12="","",IFERROR(INDEX('MASTER DATA'!$E$5:$E$12,MATCH($D12,'MASTER DATA'!$A$5:$A$12,0)),"")) | I12: =IF($D12="","",IFERROR(INDEX('MASTER DATA'!$F$5:$F$12,MATCH($D12,'MASTER DATA'!$A$5:$A$12,0)),"")) | M12: =IF(COUNT($J12:$L12)<3,"",AVERAGE($J12:$L12)) | N12: =IF($M12="","",$M12-$H12) | O12: =IF(OR($A12="",$B12="",$C12="",$D12="",COUNT($J12:$L12)<3),"INCOMPLETE",IF(ABS($N12)<=$I12,"PASS","REVIEW")) -> INCOMPLETE
E13: =IF($D13="","",IFERROR(INDEX('MASTER DATA'!$B$5:$B$12,MATCH($D13,'MASTER DATA'!$A$5:$A$12,0)),"NOT FOUND")) | F13: =IF($D13="","",IFERROR(INDEX('MASTER DATA'!$C$5:$C$12,MATCH($D13,'MASTER DATA'!$A$5:$A$12,0)),"NOT FOUND")) | G13: =IF($D13="","",IFERROR(INDEX('MASTER DATA'!$D$5:$D$12,MATCH($D13,'MASTER DATA'!$A$5:$A$12,0)),"")) | H13: =IF($D13="","",IFERROR(INDEX('MASTER DATA'!$E$5:$E$12,MATCH($D13,'MASTER DATA'!$A$5:$A$12,0)),"")) | I13: =IF($D13="","",IFERROR(INDEX('MASTER DATA'!$F$5:$F$12,MATCH($D13,'MASTER DATA'!$A$5:$A$12,0)),"")) | M13: =IF(COUNT($J13:$L13)<3,"",AVERAGE($J13:$L13)) | N13: =IF($M13="","",$M13-$H13) | O13: =IF(OR($A13="",$B13="",$C13="",$D13="",COUNT($J13:$L13)<3),"INCOMPLETE",IF(ABS($N13)<=$I13,"PASS","REVIEW")) -> INCOMPLETE
E14: =IF($D14="","",IFERROR(INDEX('MASTER DATA'!$B$5:$B$12,MATCH($D14,'MASTER DATA'!$A$5:$A$12,0)),"NOT FOUND")) | F14: =IF($D14="","",IFERROR(INDEX('MASTER DATA'!$C$5:$C$12,MATCH($D14,'MASTER DATA'!$A$5:$A$12,0)),"NOT FOUND")) | G14: =IF($D14="","",IFERROR(INDEX('MASTER DATA'!$D$5:$D$12,MATCH($D14,'MASTER DATA'!$A$5:$A$12,0)),"")) | H14: =IF($D14="","",IFERROR(INDEX('MASTER DATA'!$E$5:$E$12,MATCH($D14,'MASTER DATA'!$A$5:$A$12,0)),"")) | I14: =IF($D14="","",IFERROR(INDEX('MASTER DATA'!$F$5:$F$12,MATCH($D14,'MASTER DATA'!$A$5:$A$12,0)),"")) | M14: =IF(COUNT($J14:$L14)<3,"",AVERAGE($J14:$L14)) | N14: =IF($M14="","",$M14-$H14) | O14: =IF(OR($A14="",$B14="",$C14="",$D14="",COUNT($J14:$L14)<3),"INCOMPLETE",IF(ABS($N14)<=$I14,"PASS","REVIEW")) -> INCOMPLETE
E15: =IF($D15="","",IFERROR(INDEX('MASTER DATA'!$B$5:$B$12,MATCH($D15,'MASTER DATA'!$A$5:$A$12,0)),"NOT FOUND")) | F15: =IF($D15="","",IFERROR(INDEX('MASTER DATA'!$C$5:$C$12,MATCH($D15,'MASTER DATA'!$A$5:$A$12,0)),"NOT FOUND")) | G15: =IF($D15="","",IFERROR(INDEX('MASTER DATA'!$D$5:$D$12,MATCH($D15,'MASTER DATA'!$A$5:$A$12,0)),"")) | H15: =IF($D15="","",IFERROR(INDEX('MASTER DATA'!$E$5:$E$12,MATCH($D15,'MASTER DATA'!$A$5:$A$12,0)),"")) | I15: =IF($D15="","",IFERROR(INDEX('MASTER DATA'!$F$5:$F$12,MATCH($D15,'MASTER DATA'!$A$5:$A$12,0)),"")) | M15: =IF(COUNT($J15:$L15)<3,"",AVERAGE($J15:$L15)) | N15: =IF($M15="","",$M15-$H15) | O15: =IF(OR($A15="",$B15="",$C15="",$D15="",COUNT($J15:$L15)<3),"INCOMPLETE",IF(ABS($N15)<=$I15,"PASS","REVIEW")) -> INCOMPLETE
E16: =IF($D16="","",IFERROR(INDEX('MASTER DATA'!$B$5:$B$12,MATCH($D16,'MASTER DATA'!$A$5:$A$12,0)),"NOT FOUND")) | F16: =IF($D16="","",IFERROR(INDEX('MASTER DATA'!$C$5:$C$12,MATCH($D16,'MASTER DATA'!$A$5:$A$12,0)),"NOT FOUND")) | G16: =IF($D16="","",IFERROR(INDEX('MASTER DATA'!$D$5:$D$12,MATCH($D16,'MASTER DATA'!$A$5:$A$12,0)),"")) | H16: =IF($D16="","",IFERROR(INDEX('MASTER DATA'!$E$5:$E$12,MATCH($D16,'MASTER DATA'!$A$5:$A$12,0)),"")) | I16: =IF($D16="","",IFERROR(INDEX('MASTER DATA'!$F$5:$F$12,MATCH($D16,'MASTER DATA'!$A$5:$A$12,0)),"")) | M16: =IF(COUNT($J16:$L16)<3,"",AVERAGE($J16:$L16)) | N16: =IF($M16="","",$M16-$H16) | O16: =IF(OR($A16="",$B16="",$C16="",$D16="",COUNT($J16:$L16)<3),"INCOMPLETE",IF(ABS($N16)<=$I16,"PASS","REVIEW")) -> INCOMPLETE
E17: =IF($D17="","",IFERROR(INDEX('MASTER DATA'!$B$5:$B$12,MATCH($D17,'MASTER DATA'!$A$5:$A$12,0)),"NOT FOUND")) | F17: =IF($D17="","",IFERROR(INDEX('MASTER DATA'!$C$5:$C$12,MATCH($D17,'MASTER DATA'!$A$5:$A$12,0)),"NOT FOUND")) | G17: =IF($D17="","",IFERROR(INDEX('MASTER DATA'!$D$5:$D$12,MATCH($D17,'MASTER DATA'!$A$5:$A$12,0)),"")) | H17: =IF($D17="","",IFERROR(INDEX('MASTER DATA'!$E$5:$E$12,MATCH($D17,'MASTER DATA'!$A$5:$A$12,0)),"")) | I17: =IF($D17="","",IFERROR(INDEX('MASTER DATA'!$F$5:$F$12,MATCH($D17,'MASTER DATA'!$A$5:$A$12,0)),"")) | M17: =IF(COUNT($J17:$L17)<3,"",AVERAGE($J17:$L17)) | N17: =IF($M17="","",$M17-$H17) | O17: =IF(OR($A17="",$B17="",$C17="",$D17="",COUNT($J17:$L17)<3),"INCOMPLETE",IF(ABS($N17)<=$I17,"PASS","REVIEW")) -> INCOMPLETE
E18: =IF($D18="","",IFERROR(INDEX('MASTER DATA'!$B$5:$B$12,MATCH($D18,'MASTER DATA'!$A$5:$A$12,0)),"NOT FOUND")) | F18: =IF($D18="","",IFERROR(INDEX('MASTER DATA'!$C$5:$C$12,MATCH($D18,'MASTER DATA'!$A$5:$A$12,0)),"NOT FOUND")) | G18: =IF($D18="","",IFERROR(INDEX('MASTER DATA'!$D$5:$D$12,MATCH($D18,'MASTER DATA'!$A$5:$A$12,0)),"")) | H18: =IF($D18="","",IFERROR(INDEX('MASTER DATA'!$E$5:$E$12,MATCH($D18,'MASTER DATA'!$A$5:$A$12,0)),"")) | I18: =IF($D18="","",IFERROR(INDEX('MASTER DATA'!$F$5:$F$12,MATCH($D18,'MASTER DATA'!$A$5:$A$12,0)),"")) | M18: =IF(COUNT($J18:$L18)<3,"",AVERAGE($J18:$L18)) | N18: =IF($M18="","",$M18-$H18) | O18: =IF(OR($A18="",$B18="",$C18="",$D18="",COUNT($J18:$L18)<3),"INCOMPLETE",IF(ABS($N18)<=$I18,"PASS","REVIEW")) -> INCOMPLETE
E19: =IF($D19="","",IFERROR(INDEX('MASTER DATA'!$B$5:$B$12,MATCH($D19,'MASTER DATA'!$A$5:$A$12,0)),"NOT FOUND")) | F19: =IF($D19="","",IFERROR(INDEX('MASTER DATA'!$C$5:$C$12,MATCH($D19,'MASTER DATA'!$A$5:$A$12,0)),"NOT FOUND")) | G19: =IF($D19="","",IFERROR(INDEX('MASTER DATA'!$D$5:$D$12,MATCH($D19,'MASTER DATA'!$A$5:$A$12,0)),"")) | H19: =IF($D19="","",IFERROR(INDEX('MASTER DATA'!$E$5:$E$12,MATCH($D19,'MASTER DATA'!$A$5:$A$12,0)),"")) | I19: =IF($D19="","",IFERROR(INDEX('MASTER DATA'!$F$5:$F$12,MATCH($D19,'MASTER DATA'!$A$5:$A$12,0)),"")) | M19: =IF(COUNT($J19:$L19)<3,"",AVERAGE($J19:$L19)) | N19: =IF($M19="","",$M19-$H19) | O19: =IF(OR($A19="",$B19="",$C19="",$D19="",COUNT($J19:$L19)<3),"INCOMPLETE",IF(ABS($N19)<=$I19,"PASS","REVIEW")) -> INCOMPLETE
E20: =IF($D20="","",IFERROR(INDEX('MASTER DATA'!$B$5:$B$12,MATCH($D20,'MASTER DATA'!$A$5:$A$12,0)),"NOT FOUND")) | F20: =IF($D20="","",IFERROR(INDEX('MASTER DATA'!$C$5:$C$12,MATCH($D20,'MASTER DATA'!$A$5:$A$12,0)),"NOT FOUND")) | G20: =IF($D20="","",IFERROR(INDEX('MASTER DATA'!$D$5:$D$12,MATCH($D20,'MASTER DATA'!$A$5:$A$12,0)),"")) | H20: =IF($D20="","",IFERROR(INDEX('MASTER DATA'!$E$5:$E$12,MATCH($D20,'MASTER DATA'!$A$5:$A$12,0)),"")) | I20: =IF($D20="","",IFERROR(INDEX('MASTER DATA'!$F$5:$F$12,MATCH($D20,'MASTER DATA'!$A$5:$A$12,0)),"")) | M20: =IF(COUNT($J20:$L20)<3,"",AVERAGE($J20:$L20)) | N20: =IF($M20="","",$M20-$H20) | O20: =IF(OR($A20="",$B20="",$C20="",$D20="",COUNT($J20:$L20)<3),"INCOMPLETE",IF(ABS($N20)<=$I20,"PASS","REVIEW")) -> INCOMPLETE
E21: =IF($D21="","",IFERROR(INDEX('MASTER DATA'!$B$5:$B$12,MATCH($D21,'MASTER DATA'!$A$5:$A$12,0)),"NOT FOUND")) | F21: =IF($D21="","",IFERROR(INDEX('MASTER DATA'!$C$5:$C$12,MATCH($D21,'MASTER DATA'!$A$5:$A$12,0)),"NOT FOUND")) | G21: =IF($D21="","",IFERROR(INDEX('MASTER DATA'!$D$5:$D$12,MATCH($D21,'MASTER DATA'!$A$5:$A$12,0)),"")) | H21: =IF($D21="","",IFERROR(INDEX('MASTER DATA'!$E$5:$E$12,MATCH($D21,'MASTER DATA'!$A$5:$A$12,0)),"")) | I21: =IF($D21="","",IFERROR(INDEX('MASTER DATA'!$F$5:$F$12,MATCH($D21,'MASTER DATA'!$A$5:$A$12,0)),"")) | M21: =IF(COUNT($J21:$L21)<3,"",AVERAGE($J21:$L21)) | N21: =IF($M21="","",$M21-$H21) | O21: =IF(OR($A21="",$B21="",$C21="",$D21="",COUNT($J21:$L21)<3),"INCOMPLETE",IF(ABS($N21)<=$I21,"PASS","REVIEW")) -> INCOMPLETE
... E54: =IF($D54="","",IFERROR(INDEX('MASTER DATA'!$B$5:$B$12,MATCH($D54,'MASTER DATA'!$A$5:$A$12,0)),"NOT FOUND")) | F54: =IF($D54="","",IFERROR(INDEX('MASTER DATA'!$C$5:$C$12,MATCH($D54,'MASTER DATA'!$A$5:$A$12,0)),"NOT FOUND")) | G54: =IF($D54="","",IFERROR(INDEX('MASTER DATA'!$D$5:$D$12,MATCH($D54,'MASTER DATA'!$A$5:$A$12,0)),"")) | H54: =IF($D54="","",IFERROR(INDEX('MASTER DATA'!$E$5:$E$12,MATCH($D54,'MASTER DATA'!$A$5:$A$12,0)),"")) | I54: =IF($D54="","",IFERROR(INDEX('MASTER DATA'!$F$5:$F$12,MATCH($D54,'MASTER DATA'!$A$5:$A$12,0)),"")) | M54: =IF(COUNT($J54:$L54)<3,"",AVERAGE($J54:$L54)) | N54: =IF($M54="","",$M54-$H54) | O54: =IF(OR($A54="",$B54="",$C54="",$D54="",COUNT($J54:$L54)<3),"INCOMPLETE",IF(ABS($N54)<=$I54,"PASS","REVIEW")) -> INCOMPLETE

Sheet CALCULATION
A1: RINCIAN PERHITUNGAN
A2: Sheet ini hanya untuk dibaca. Setiap baris mengikuti data pada INPUT LOG.
A4: Baris | B4: Work Order | C4: Asset ID | D4: Nilai acuan | E4: Toleransi | F4: Rata-rata | G4: Selisih | H4: Aturan | I4: Status
A5: 5 | B5: ='INPUT LOG'!A5 -> WO-2401 | C5: ='INPUT LOG'!D5 -> AST-001 | D5: ='INPUT LOG'!H5 -> 5 | E5: ='INPUT LOG'!I5 -> 0.1 | F5: ='INPUT LOG'!M5 -> 5.02 | G5: ='INPUT LOG'!N5 -> 0.02 | H5: ABS(Selisih) <= Toleransi | I5: ='INPUT LOG'!O5 -> PASS
A6: 6 | B6: ='INPUT LOG'!A6 -> WO-2402 | C6: ='INPUT LOG'!D6 -> AST-002 | D6: ='INPUT LOG'!H6 -> 100 | E6: ='INPUT LOG'!I6 -> 0.5 | F6: ='INPUT LOG'!M6 -> 100.2 | G6: ='INPUT LOG'!N6 -> 0.2 | H6: ABS(Selisih) <= Toleransi | I6: ='INPUT LOG'!O6 -> PASS
A7: 7 | B7: ='INPUT LOG'!A7 -> WO-2403 | C7: ='INPUT LOG'!D7 -> AST-003 | D7: ='INPUT LOG'!H7 -> 50 | E7: ='INPUT LOG'!I7 -> 1 | F7: ='INPUT LOG'!M7 -> 51.1 | G7: ='INPUT LOG'!N7 -> 1.1 | H7: ABS(Selisih) <= Toleransi | I7: ='INPUT LOG'!O7 -> REVIEW
A8: 8 | B8: ='INPUT LOG'!A8 -> WO-2404 | C8: ='INPUT LOG'!D8 -> AST-004 | D8: ='INPUT LOG'!H8 -> 25 | E8: ='INPUT LOG'!I8 -> 0.05 | F8: ='INPUT LOG'!M8 -> 25.013333 | G8: ='INPUT LOG'!N8 -> 0.013333333 | H8: ABS(Selisih) <= Toleransi | I8: ='INPUT LOG'!O8 -> PASS
A9: 9 | B9: ='INPUT LOG'!A9 -> WO-2405 | C9: ='INPUT LOG'!D9 -> AST-006 | D9: ='INPUT LOG'!H9 -> 10 | E9: ='INPUT LOG'!I9 -> 0.02 | F9: ='INPUT LOG'!M9 -> 10.033333 | G9: ='INPUT LOG'!N9 -> 0.033333333 | H9: ABS(Selisih) <= Toleransi | I9: ='INPUT LOG'!O9 -> REVIEW
A10: 10 | B10: ='INPUT LOG'!A10 -> 0 | C10: ='INPUT LOG'!D10 -> 0 | D10: ='INPUT LOG'!H10 | E10: ='INPUT LOG'!I10 | F10: ='INPUT LOG'!M10 | G10: ='INPUT LOG'!N10 | H10: ABS(Selisih) <= Toleransi | I10: ='INPUT LOG'!O10 -> INCOMPLETE
A11: 11 | B11: ='INPUT LOG'!A11 -> 0 | C11: ='INPUT LOG'!D11 -> 0 | D11: ='INPUT LOG'!H11 | E11: ='INPUT LOG'!I11 | F11: ='INPUT LOG'!M11 | G11: ='INPUT LOG'!N11 | H11: ABS(Selisih) <= Toleransi | I11: ='INPUT LOG'!O11 -> INCOMPLETE
A12: 12 | B12: ='INPUT LOG'!A12 -> 0 | C12: ='INPUT LOG'!D12 -> 0 | D12: ='INPUT LOG'!H12 | E12: ='INPUT LOG'!I12 | F12: ='INPUT LOG'!M12 | G12: ='INPUT LOG'!N12 | H12: ABS(Selisih) <= Toleransi | I12: ='INPUT LOG'!O12 -> INCOMPLETE
A13: 13 | B13: ='INPUT LOG'!A13 -> 0 | C13: ='INPUT LOG'!D13 -> 0 | D13: ='INPUT LOG'!H13 | E13: ='INPUT LOG'!I13 | F13: ='INPUT LOG'!M13 | G13: ='INPUT LOG'!N13 | H13: ABS(Selisih) <= Toleransi | I13: ='INPUT LOG'!O13 -> INCOMPLETE
A14: 14 | B14: ='INPUT LOG'!A14 -> 0 | C14: ='INPUT LOG'!D14 -> 0 | D14: ='INPUT LOG'!H14 | E14: ='INPUT LOG'!I14 | F14: ='INPUT LOG'!M14 | G14: ='INPUT LOG'!N14 | H14: ABS(Selisih) <= Toleransi | I14: ='INPUT LOG'!O14 -> INCOMPLETE
A15: 15 | B15: ='INPUT LOG'!A15 -> 0 | C15: ='INPUT LOG'!D15 -> 0 | D15: ='INPUT LOG'!H15 | E15: ='INPUT LOG'!I15 | F15: ='INPUT LOG'!M15 | G15: ='INPUT LOG'!N15 | H15: ABS(Selisih) <= Toleransi | I15: ='INPUT LOG'!O15 -> INCOMPLETE
A16: 16 | B16: ='INPUT LOG'!A16 -> 0 | C16: ='INPUT LOG'!D16 -> 0 | D16: ='INPUT LOG'!H16 | E16: ='INPUT LOG'!I16 | F16: ='INPUT LOG'!M16 | G16: ='INPUT LOG'!N16 | H16: ABS(Selisih) <= Toleransi | I16: ='INPUT LOG'!O16 -> INCOMPLETE
... A54: 54 | B54: ='INPUT LOG'!A54 -> 0 | C54: ='INPUT LOG'!D54 -> 0 | D54: ='INPUT LOG'!H54 | E54: ='INPUT LOG'!I54 | F54: ='INPUT LOG'!M54 | G54: ='INPUT LOG'!N54 | H54: ABS(Selisih) <= Toleransi | I54: ='INPUT LOG'!O54 -> INCOMPLETE

Sheet REPORT
A1: RINGKASAN HASIL
A2: Angka pada sheet ini dibaca langsung dari INPUT LOG.
A4: Selesai diisi | D4: PASS | G4: Perlu diperiksa | J4: Belum lengkap
A5: =COUNTIF('INPUT LOG'!$O$5:$O$54,"PASS")+COUNTIF('INPUT LOG'!$O$5:$O$54,"REVIEW") -> 5 | D5: =COUNTIF('INPUT LOG'!$O$5:$O$54,"PASS") -> 3 | G5: =COUNTIF('INPUT LOG'!$O$5:$O$54,"REVIEW") -> 2 | J5: =COUNTIF('INPUT LOG'!$O$5:$O$54,"INCOMPLETE")-COUNTBLANK('INPUT LOG'!$A$5:$A$54) -> 0
A9: Daftar pekerjaan
A10: Work Order | B10: Tanggal | C10: Teknisi | D10: Asset ID | E10: Nama alat | F10: Rata-rata | G10: Selisih | H10: Status
A11: =IF('INPUT LOG'!$A$5="","",'INPUT LOG'!$A$5) -> WO-2401 | B11: =IF('INPUT LOG'!$A$5="","",'INPUT LOG'!$B$5) -> 46286 | C11: =IF('INPUT LOG'!$A$5="","",'INPUT LOG'!$C$5) -> Ayu Pratama | D11: =IF('INPUT LOG'!$A$5="","",'INPUT LOG'!$D$5) -> AST-001 | E11: =IF('INPUT LOG'!$A$5="","",'INPUT LOG'!$E$5) -> Pressure Gauge 0 to 10 bar | F11: =IF('INPUT LOG'!$A$5="","",'INPUT LOG'!$M$5) -> 5.02 | G11: =IF('INPUT LOG'!$A$5="","",'INPUT LOG'!$N$5) -> 0.02 | H11: =IF('INPUT LOG'!$A$5="","",'INPUT LOG'!$O$5) -> PASS
A12: =IF('INPUT LOG'!$A$6="","",'INPUT LOG'!$A$6) -> WO-2402 | B12: =IF('INPUT LOG'!$A$6="","",'INPUT LOG'!$B$6) -> 46287 | C12: =IF('INPUT LOG'!$A$6="","",'INPUT LOG'!$C$6) -> Bima Santoso | D12: =IF('INPUT LOG'!$A$6="","",'INPUT LOG'!$D$6) -> AST-002 | E12: =IF('INPUT LOG'!$A$6="","",'INPUT LOG'!$E$6) -> Temperature Sensor | F12: =IF('INPUT LOG'!$A$6="","",'INPUT LOG'!$M$6) -> 100.2 | G12: =IF('INPUT LOG'!$A$6="","",'INPUT LOG'!$N$6) -> 0.2 | H12: =IF('INPUT LOG'!$A$6="","",'INPUT LOG'!$O$6) -> PASS
A13: =IF('INPUT LOG'!$A$7="","",'INPUT LOG'!$A$7) -> WO-2403 | B13: =IF('INPUT LOG'!$A$7="","",'INPUT LOG'!$B$7) -> 46288 | C13: =IF('INPUT LOG'!$A$7="","",'INPUT LOG'!$C$7) -> Citra Lestari | D13: =IF('INPUT LOG'!$A$7="","",'INPUT LOG'!$D$7) -> AST-003 | E13: =IF('INPUT LOG'!$A$7="","",'INPUT LOG'!$E$7) -> Flow Meter | F13: =IF('INPUT LOG'!$A$7="","",'INPUT LOG'!$M$7) -> 51.1 | G13: =IF('INPUT LOG'!$A$7="","",'INPUT LOG'!$N$7) -> 1.1 | H13: =IF('INPUT LOG'!$A$7="","",'INPUT LOG'!$O$7) -> REVIEW
A14: =IF('INPUT LOG'!$A$8="","",'INPUT LOG'!$A$8) -> WO-2404 | B14: =IF('INPUT LOG'!$A$8="","",'INPUT LOG'!$B$8) -> 46289 | C14: =IF('INPUT LOG'!$A$8="","",'INPUT LOG'!$C$8) -> Danu Wijaya | D14: =IF('INPUT LOG'!$A$8="","",'INPUT LOG'!$D$8) -> AST-004 | E14: =IF('INPUT LOG'!$A$8="","",'INPUT LOG'!$E$8) -> Digital Caliper | F14: =IF('INPUT LOG'!$A$8="","",'INPUT LOG'!$M$8) -> 25.013333 | G14: =IF('INPUT LOG'!$A$8="","",'INPUT LOG'!$N$8) -> 0.013333333 | H14: =IF('INPUT LOG'!$A$8="","",'INPUT LOG'!$O$8) -> PASS
A15: =IF('INPUT LOG'!$A$9="","",'INPUT LOG'!$A$9) -> WO-2405 | B15: =IF('INPUT LOG'!$A$9="","",'INPUT LOG'!$B$9) -> 46290 | C15: =IF('INPUT LOG'!$A$9="","",'INPUT LOG'!$C$9) -> Ayu Pratama | D15: =IF('INPUT LOG'!$A$9="","",'INPUT LOG'!$D$9) -> AST-006 | E15: =IF('INPUT LOG'!$A$9="","",'INPUT LOG'!$E$9) -> Weighing Scale | F15: =IF('INPUT LOG'!$A$9="","",'INPUT LOG'!$M$9) -> 10.033333 | G15: =IF('INPUT LOG'!$A$9="","",'INPUT LOG'!$N$9) -> 0.033333333 | H15: =IF('INPUT LOG'!$A$9="","",'INPUT LOG'!$O$9) -> REVIEW
A16: =IF('INPUT LOG'!$A$10="","",'INPUT LOG'!$A$10) | B16: =IF('INPUT LOG'!$A$10="","",'INPUT LOG'!$B$10) | C16: =IF('INPUT LOG'!$A$10="","",'INPUT LOG'!$C$10) | D16: =IF('INPUT LOG'!$A$10="","",'INPUT LOG'!$D$10) | E16: =IF('INPUT LOG'!$A$10="","",'INPUT LOG'!$E$10) | F16: =IF('INPUT LOG'!$A$10="","",'INPUT LOG'!$M$10) | G16: =IF('INPUT LOG'!$A$10="","",'INPUT LOG'!$N$10) | H16: =IF('INPUT LOG'!$A$10="","",'INPUT LOG'!$O$10)
A17: =IF('INPUT LOG'!$A$11="","",'INPUT LOG'!$A$11) | B17: =IF('INPUT LOG'!$A$11="","",'INPUT LOG'!$B$11) | C17: =IF('INPUT LOG'!$A$11="","",'INPUT LOG'!$C$11) | D17: =IF('INPUT LOG'!$A$11="","",'INPUT LOG'!$D$11) | E17: =IF('INPUT LOG'!$A$11="","",'INPUT LOG'!$E$11) | F17: =IF('INPUT LOG'!$A$11="","",'INPUT LOG'!$M$11) | G17: =IF('INPUT LOG'!$A$11="","",'INPUT LOG'!$N$11) | H17: =IF('INPUT LOG'!$A$11="","",'INPUT LOG'!$O$11)
A18: =IF('INPUT LOG'!$A$12="","",'INPUT LOG'!$A$12) | B18: =IF('INPUT LOG'!$A$12="","",'INPUT LOG'!$B$12) | C18: =IF('INPUT LOG'!$A$12="","",'INPUT LOG'!$C$12) | D18: =IF('INPUT LOG'!$A$12="","",'INPUT LOG'!$D$12) | E18: =IF('INPUT LOG'!$A$12="","",'INPUT LOG'!$E$12) | F18: =IF('INPUT LOG'!$A$12="","",'INPUT LOG'!$M$12) | G18: =IF('INPUT LOG'!$A$12="","",'INPUT LOG'!$N$12) | H18: =IF('INPUT LOG'!$A$12="","",'INPUT LOG'!$O$12)
A19: =IF('INPUT LOG'!$A$13="","",'INPUT LOG'!$A$13) | B19: =IF('INPUT LOG'!$A$13="","",'INPUT LOG'!$B$13) | C19: =IF('INPUT LOG'!$A$13="","",'INPUT LOG'!$C$13) | D19: =IF('INPUT LOG'!$A$13="","",'INPUT LOG'!$D$13) | E19: =IF('INPUT LOG'!$A$13="","",'INPUT LOG'!$E$13) | F19: =IF('INPUT LOG'!$A$13="","",'INPUT LOG'!$M$13) | G19: =IF('INPUT LOG'!$A$13="","",'INPUT LOG'!$N$13) | H19: =IF('INPUT LOG'!$A$13="","",'INPUT LOG'!$O$13)
A20: =IF('INPUT LOG'!$A$14="","",'INPUT LOG'!$A$14) | B20: =IF('INPUT LOG'!$A$14="","",'INPUT LOG'!$B$14) | C20: =IF('INPUT LOG'!$A$14="","",'INPUT LOG'!$C$14) | D20: =IF('INPUT LOG'!$A$14="","",'INPUT LOG'!$D$14) | E20: =IF('INPUT LOG'!$A$14="","",'INPUT LOG'!$E$14) | F20: =IF('INPUT LOG'!$A$14="","",'INPUT LOG'!$M$14) | G20: =IF('INPUT LOG'!$A$14="","",'INPUT LOG'!$N$14) | H20: =IF('INPUT LOG'!$A$14="","",'INPUT LOG'!$O$14)
A21: =IF('INPUT LOG'!$A$15="","",'INPUT LOG'!$A$15) | B21: =IF('INPUT LOG'!$A$15="","",'INPUT LOG'!$B$15) | C21: =IF('INPUT LOG'!$A$15="","",'INPUT LOG'!$C$15) | D21: =IF('INPUT LOG'!$A$15="","",'INPUT LOG'!$D$15) | E21: =IF('INPUT LOG'!$A$15="","",'INPUT LOG'!$E$15) | F21: =IF('INPUT LOG'!$A$15="","",'INPUT LOG'!$M$15) | G21: =IF('INPUT LOG'!$A$15="","",'INPUT LOG'!$N$15) | H21: =IF('INPUT LOG'!$A$15="","",'INPUT LOG'!$O$15)
A22: =IF('INPUT LOG'!$A$16="","",'INPUT LOG'!$A$16) | B22: =IF('INPUT LOG'!$A$16="","",'INPUT LOG'!$B$16) | C22: =IF('INPUT LOG'!$A$16="","",'INPUT LOG'!$C$16) | D22: =IF('INPUT LOG'!$A$16="","",'INPUT LOG'!$D$16) | E22: =IF('INPUT LOG'!$A$16="","",'INPUT LOG'!$E$16) | F22: =IF('INPUT LOG'!$A$16="","",'INPUT LOG'!$M$16) | G22: =IF('INPUT LOG'!$A$16="","",'INPUT LOG'!$N$16) | H22: =IF('INPUT LOG'!$A$16="","",'INPUT LOG'!$O$16)
A23: =IF('INPUT LOG'!$A$17="","",'INPUT LOG'!$A$17) | B23: =IF('INPUT LOG'!$A$17="","",'INPUT LOG'!$B$17) | C23: =IF('INPUT LOG'!$A$17="","",'INPUT LOG'!$C$17) | D23: =IF('INPUT LOG'!$A$17="","",'INPUT LOG'!$D$17) | E23: =IF('INPUT LOG'!$A$17="","",'INPUT LOG'!$E$17) | F23: =IF('INPUT LOG'!$A$17="","",'INPUT LOG'!$M$17) | G23: =IF('INPUT LOG'!$A$17="","",'INPUT LOG'!$N$17) | H23: =IF('INPUT LOG'!$A$17="","",'INPUT LOG'!$O$17)
A24: =IF('INPUT LOG'!$A$18="","",'INPUT LOG'!$A$18) | B24: =IF('INPUT LOG'!$A$18="","",'INPUT LOG'!$B$18) | C24: =IF('INPUT LOG'!$A$18="","",'INPUT LOG'!$C$18) | D24: =IF('INPUT LOG'!$A$18="","",'INPUT LOG'!$D$18) | E24: =IF('INPUT LOG'!$A$18="","",'INPUT LOG'!$E$18) | F24: =IF('INPUT LOG'!$A$18="","",'INPUT LOG'!$M$18) | G24: =IF('INPUT LOG'!$A$18="","",'INPUT LOG'!$N$18) | H24: =IF('INPUT LOG'!$A$18="","",'INPUT LOG'!$O$18)
A25: =IF('INPUT LOG'!$A$19="","",'INPUT LOG'!$A$19) | B25: =IF('INPUT LOG'!$A$19="","",'INPUT LOG'!$B$19) | C25: =IF('INPUT LOG'!$A$19="","",'INPUT LOG'!$C$19) | D25: =IF('INPUT LOG'!$A$19="","",'INPUT LOG'!$D$19) | E25: =IF('INPUT LOG'!$A$19="","",'INPUT LOG'!$E$19) | F25: =IF('INPUT LOG'!$A$19="","",'INPUT LOG'!$M$19) | G25: =IF('INPUT LOG'!$A$19="","",'INPUT LOG'!$N$19) | H25: =IF('INPUT LOG'!$A$19="","",'INPUT LOG'!$O$19)
A26: =IF('INPUT LOG'!$A$20="","",'INPUT LOG'!$A$20) | B26: =IF('INPUT LOG'!$A$20="","",'INPUT LOG'!$B$20) | C26: =IF('INPUT LOG'!$A$20="","",'INPUT LOG'!$C$20) | D26: =IF('INPUT LOG'!$A$20="","",'INPUT LOG'!$D$20) | E26: =IF('INPUT LOG'!$A$20="","",'INPUT LOG'!$E$20) | F26: =IF('INPUT LOG'!$A$20="","",'INPUT LOG'!$M$20) | G26: =IF('INPUT LOG'!$A$20="","",'INPUT LOG'!$N$20) | H26: =IF('INPUT LOG'!$A$20="","",'INPUT LOG'!$O$20)
A27: =IF('INPUT LOG'!$A$21="","",'INPUT LOG'!$A$21) | B27: =IF('INPUT LOG'!$A$21="","",'INPUT LOG'!$B$21) | C27: =IF('INPUT LOG'!$A$21="","",'INPUT LOG'!$C$21) | D27: =IF('INPUT LOG'!$A$21="","",'INPUT LOG'!$D$21) | E27: =IF('INPUT LOG'!$A$21="","",'INPUT LOG'!$E$21) | F27: =IF('INPUT LOG'!$A$21="","",'INPUT LOG'!$M$21) | G27: =IF('INPUT LOG'!$A$21="","",'INPUT LOG'!$N$21) | H27: =IF('INPUT LOG'!$A$21="","",'INPUT LOG'!$O$21)
A28: =IF('INPUT LOG'!$A$22="","",'INPUT LOG'!$A$22) | B28: =IF('INPUT LOG'!$A$22="","",'INPUT LOG'!$B$22) | C28: =IF('INPUT LOG'!$A$22="","",'INPUT LOG'!$C$22) | D28: =IF('INPUT LOG'!$A$22="","",'INPUT LOG'!$D$22) | E28: =IF('INPUT LOG'!$A$22="","",'INPUT LOG'!$E$22) | F28: =IF('INPUT LOG'!$A$22="","",'INPUT LOG'!$M$22) | G28: =IF('INPUT LOG'!$A$22="","",'INPUT LOG'!$N$22) | H28: =IF('INPUT LOG'!$A$22="","",'INPUT LOG'!$O$22)
A29: =IF('INPUT LOG'!$A$23="","",'INPUT LOG'!$A$23) | B29: =IF('INPUT LOG'!$A$23="","",'INPUT LOG'!$B$23) | C29: =IF('INPUT LOG'!$A$23="","",'INPUT LOG'!$C$23) | D29: =IF('INPUT LOG'!$A$23="","",'INPUT LOG'!$D$23) | E29: =IF('INPUT LOG'!$A$23="","",'INPUT LOG'!$E$23) | F29: =IF('INPUT LOG'!$A$23="","",'INPUT LOG'!$M$23) | G29: =IF('INPUT LOG'!$A$23="","",'INPUT LOG'!$N$23) | H29: =IF('INPUT LOG'!$A$23="","",'INPUT LOG'!$O$23)
A30: =IF('INPUT LOG'!$A$24="","",'INPUT LOG'!$A$24) | B30: =IF('INPUT LOG'!$A$24="","",'INPUT LOG'!$B$24) | C30: =IF('INPUT LOG'!$A$24="","",'INPUT LOG'!$C$24) | D30: =IF('INPUT LOG'!$A$24="","",'INPUT LOG'!$D$24) | E30: =IF('INPUT LOG'!$A$24="","",'INPUT LOG'!$E$24) | F30: =IF('INPUT LOG'!$A$24="","",'INPUT LOG'!$M$24) | G30: =IF('INPUT LOG'!$A$24="","",'INPUT LOG'!$N$24) | H30: =IF('INPUT LOG'!$A$24="","",'INPUT LOG'!$O$24)
A31: =IF('INPUT LOG'!$A$25="","",'INPUT LOG'!$A$25) | B31: =IF('INPUT LOG'!$A$25="","",'INPUT LOG'!$B$25) | C31: =IF('INPUT LOG'!$A$25="","",'INPUT LOG'!$C$25) | D31: =IF('INPUT LOG'!$A$25="","",'INPUT LOG'!$D$25) | E31: =IF('INPUT LOG'!$A$25="","",'INPUT LOG'!$E$25) | F31: =IF('INPUT LOG'!$A$25="","",'INPUT LOG'!$M$25) | G31: =IF('INPUT LOG'!$A$25="","",'INPUT LOG'!$N$25) | H31: =IF('INPUT LOG'!$A$25="","",'INPUT LOG'!$O$25)
A32: =IF('INPUT LOG'!$A$26="","",'INPUT LOG'!$A$26) | B32: =IF('INPUT LOG'!$A$26="","",'INPUT LOG'!$B$26) | C32: =IF('INPUT LOG'!$A$26="","",'INPUT LOG'!$C$26) | D32: =IF('INPUT LOG'!$A$26="","",'INPUT LOG'!$D$26) | E32: =IF('INPUT LOG'!$A$26="","",'INPUT LOG'!$E$26) | F32: =IF('INPUT LOG'!$A$26="","",'INPUT LOG'!$M$26) | G32: =IF('INPUT LOG'!$A$26="","",'INPUT LOG'!$N$26) | H32: =IF('INPUT LOG'!$A$26="","",'INPUT LOG'!$O$26)
A33: =IF('INPUT LOG'!$A$27="","",'INPUT LOG'!$A$27) | B33: =IF('INPUT LOG'!$A$27="","",'INPUT LOG'!$B$27) | C33: =IF('INPUT LOG'!$A$27="","",'INPUT LOG'!$C$27) | D33: =IF('INPUT LOG'!$A$27="","",'INPUT LOG'!$D$27) | E33: =IF('INPUT LOG'!$A$27="","",'INPUT LOG'!$E$27) | F33: =IF('INPUT LOG'!$A$27="","",'INPUT LOG'!$M$27) | G33: =IF('INPUT LOG'!$A$27="","",'INPUT LOG'!$N$27) | H33: =IF('INPUT LOG'!$A$27="","",'INPUT LOG'!$O$27)
A34: =IF('INPUT LOG'!$A$28="","",'INPUT LOG'!$A$28) | B34: =IF('INPUT LOG'!$A$28="","",'INPUT LOG'!$B$28) | C34: =IF('INPUT LOG'!$A$28="","",'INPUT LOG'!$C$28) | D34: =IF('INPUT LOG'!$A$28="","",'INPUT LOG'!$D$28) | E34: =IF('INPUT LOG'!$A$28="","",'INPUT LOG'!$E$28) | F34: =IF('INPUT LOG'!$A$28="","",'INPUT LOG'!$M$28) | G34: =IF('INPUT LOG'!$A$28="","",'INPUT LOG'!$N$28) | H34: =IF('INPUT LOG'!$A$28="","",'INPUT LOG'!$O$28)
A35: =IF('INPUT LOG'!$A$29="","",'INPUT LOG'!$A$29) | B35: =IF('INPUT LOG'!$A$29="","",'INPUT LOG'!$B$29) | C35: =IF('INPUT LOG'!$A$29="","",'INPUT LOG'!$C$29) | D35: =IF('INPUT LOG'!$A$29="","",'INPUT LOG'!$D$29) | E35: =IF('INPUT LOG'!$A$29="","",'INPUT LOG'!$E$29) | F35: =IF('INPUT LOG'!$A$29="","",'INPUT LOG'!$M$29) | G35: =IF('INPUT LOG'!$A$29="","",'INPUT LOG'!$N$29) | H35: =IF('INPUT LOG'!$A$29="","",'INPUT LOG'!$O$29)
A36: =IF('INPUT LOG'!$A$30="","",'INPUT LOG'!$A$30) | B36: =IF('INPUT LOG'!$A$30="","",'INPUT LOG'!$B$30) | C36: =IF('INPUT LOG'!$A$30="","",'INPUT LOG'!$C$30) | D36: =IF('INPUT LOG'!$A$30="","",'INPUT LOG'!$D$30) | E36: =IF('INPUT LOG'!$A$30="","",'INPUT LOG'!$E$30) | F36: =IF('INPUT LOG'!$A$30="","",'INPUT LOG'!$M$30) | G36: =IF('INPUT LOG'!$A$30="","",'INPUT LOG'!$N$30) | H36: =IF('INPUT LOG'!$A$30="","",'INPUT LOG'!$O$30)
A37: =IF('INPUT LOG'!$A$31="","",'INPUT LOG'!$A$31) | B37: =IF('INPUT LOG'!$A$31="","",'INPUT LOG'!$B$31) | C37: =IF('INPUT LOG'!$A$31="","",'INPUT LOG'!$C$31) | D37: =IF('INPUT LOG'!$A$31="","",'INPUT LOG'!$D$31) | E37: =IF('INPUT LOG'!$A$31="","",'INPUT LOG'!$E$31) | F37: =IF('INPUT LOG'!$A$31="","",'INPUT LOG'!$M$31) | G37: =IF('INPUT LOG'!$A$31="","",'INPUT LOG'!$N$31) | H37: =IF('INPUT LOG'!$A$31="","",'INPUT LOG'!$O$31)
A38: =IF('INPUT LOG'!$A$32="","",'INPUT LOG'!$A$32) | B38: =IF('INPUT LOG'!$A$32="","",'INPUT LOG'!$B$32) | C38: =IF('INPUT LOG'!$A$32="","",'INPUT LOG'!$C$32) | D38: =IF('INPUT LOG'!$A$32="","",'INPUT LOG'!$D$32) | E38: =IF('INPUT LOG'!$A$32="","",'INPUT LOG'!$E$32) | F38: =IF('INPUT LOG'!$A$32="","",'INPUT LOG'!$M$32) | G38: =IF('INPUT LOG'!$A$32="","",'INPUT LOG'!$N$32) | H38: =IF('INPUT LOG'!$A$32="","",'INPUT LOG'!$O$32)
A39: =IF('INPUT LOG'!$A$33="","",'INPUT LOG'!$A$33) | B39: =IF('INPUT LOG'!$A$33="","",'INPUT LOG'!$B$33) | C39: =IF('INPUT LOG'!$A$33="","",'INPUT LOG'!$C$33) | D39: =IF('INPUT LOG'!$A$33="","",'INPUT LOG'!$D$33) | E39: =IF('INPUT LOG'!$A$33="","",'INPUT LOG'!$E$33) | F39: =IF('INPUT LOG'!$A$33="","",'INPUT LOG'!$M$33) | G39: =IF('INPUT LOG'!$A$33="","",'INPUT LOG'!$N$33) | H39: =IF('INPUT LOG'!$A$33="","",'INPUT LOG'!$O$33)
A40: =IF('INPUT LOG'!$A$34="","",'INPUT LOG'!$A$34) | B40: =IF('INPUT LOG'!$A$34="","",'INPUT LOG'!$B$34) | C40: =IF('INPUT LOG'!$A$34="","",'INPUT LOG'!$C$34) | D40: =IF('INPUT LOG'!$A$34="","",'INPUT LOG'!$D$34) | E40: =IF('INPUT LOG'!$A$34="","",'INPUT LOG'!$E$34) | F40: =IF('INPUT LOG'!$A$34="","",'INPUT LOG'!$M$34) | G40: =IF('INPUT LOG'!$A$34="","",'INPUT LOG'!$N$34) | H40: =IF('INPUT LOG'!$A$34="","",'INPUT LOG'!$O$34)
A41: =IF('INPUT LOG'!$A$35="","",'INPUT LOG'!$A$35) | B41: =IF('INPUT LOG'!$A$35="","",'INPUT LOG'!$B$35) | C41: =IF('INPUT LOG'!$A$35="","",'INPUT LOG'!$C$35) | D41: =IF('INPUT LOG'!$A$35="","",'INPUT LOG'!$D$35) | E41: =IF('INPUT LOG'!$A$35="","",'INPUT LOG'!$E$35) | F41: =IF('INPUT LOG'!$A$35="","",'INPUT LOG'!$M$35) | G41: =IF('INPUT LOG'!$A$35="","",'INPUT LOG'!$N$35) | H41: =IF('INPUT LOG'!$A$35="","",'INPUT LOG'!$O$35)
A42: =IF('INPUT LOG'!$A$36="","",'INPUT LOG'!$A$36) | B42: =IF('INPUT LOG'!$A$36="","",'INPUT LOG'!$B$36) | C42: =IF('INPUT LOG'!$A$36="","",'INPUT LOG'!$C$36) | D42: =IF('INPUT LOG'!$A$36="","",'INPUT LOG'!$D$36) | E42: =IF('INPUT LOG'!$A$36="","",'INPUT LOG'!$E$36) | F42: =IF('INPUT LOG'!$A$36="","",'INPUT LOG'!$M$36) | G42: =IF('INPUT LOG'!$A$36="","",'INPUT LOG'!$N$36) | H42: =IF('INPUT LOG'!$A$36="","",'INPUT LOG'!$O$36)
A43: =IF('INPUT LOG'!$A$37="","",'INPUT LOG'!$A$37) | B43: =IF('INPUT LOG'!$A$37="","",'INPUT LOG'!$B$37) | C43: =IF('INPUT LOG'!$A$37="","",'INPUT LOG'!$C$37) | D43: =IF('INPUT LOG'!$A$37="","",'INPUT LOG'!$D$37) | E43: =IF('INPUT LOG'!$A$37="","",'INPUT LOG'!$E$37) | F43: =IF('INPUT LOG'!$A$37="","",'INPUT LOG'!$M$37) | G43: =IF('INPUT LOG'!$A$37="","",'INPUT LOG'!$N$37) | H43: =IF('INPUT LOG'!$A$37="","",'INPUT LOG'!$O$37)
A44: =IF('INPUT LOG'!$A$38="","",'INPUT LOG'!$A$38) | B44: =IF('INPUT LOG'!$A$38="","",'INPUT LOG'!$B$38) | C44: =IF('INPUT LOG'!$A$38="","",'INPUT LOG'!$C$38) | D44: =IF('INPUT LOG'!$A$38="","",'INPUT LOG'!$D$38) | E44: =IF('INPUT LOG'!$A$38="","",'INPUT LOG'!$E$38) | F44: =IF('INPUT LOG'!$A$38="","",'INPUT LOG'!$M$38) | G44: =IF('INPUT LOG'!$A$38="","",'INPUT LOG'!$N$38) | H44: =IF('INPUT LOG'!$A$38="","",'INPUT LOG'!$O$38)
...

Sheet VALIDATION
A1: PEMERIKSAAN HASIL
A2: Nilai acuan di kolom kuning dibandingkan dengan hasil hitung workbook.
A4: Test ID | B4: Work Order | C4: Rata-rata acuan | D4: Hasil workbook | E4: Status acuan | F4: Status workbook | G4: Hasil cek | H4: Catatan
A5: TC-001 | B5: WO-2401 | C5: 5.02 | D5: =IFERROR(INDEX('INPUT LOG'!$M$5:$M$54,MATCH($B5,'INPUT LOG'!$A$5:$A$54,0)),"") -> 5.02 | E5: PASS | F5: =IFERROR(INDEX('INPUT LOG'!$O$5:$O$54,MATCH($B5,'INPUT LOG'!$A$5:$A$54,0)),"") -> PASS | G5: =IF(AND(ABS($C5-$D5)<0.000001,$E5=$F5),"PASS","CHECK") -> PASS | H5: Tekanan masih dalam toleransi
A6: TC-002 | B6: WO-2402 | C6: 100.2 | D6: =IFERROR(INDEX('INPUT LOG'!$M$5:$M$54,MATCH($B6,'INPUT LOG'!$A$5:$A$54,0)),"") -> 100.2 | E6: PASS | F6: =IFERROR(INDEX('INPUT LOG'!$O$5:$O$54,MATCH($B6,'INPUT LOG'!$A$5:$A$54,0)),"") -> PASS | G6: =IF(AND(ABS($C6-$D6)<0.000001,$E6=$F6),"PASS","CHECK") -> PASS | H6: Suhu masih dalam toleransi
A7: TC-003 | B7: WO-2403 | C7: 51.1 | D7: =IFERROR(INDEX('INPUT LOG'!$M$5:$M$54,MATCH($B7,'INPUT LOG'!$A$5:$A$54,0)),"") -> 51.1 | E7: REVIEW | F7: =IFERROR(INDEX('INPUT LOG'!$O$5:$O$54,MATCH($B7,'INPUT LOG'!$A$5:$A$54,0)),"") -> REVIEW | G7: =IF(AND(ABS($C7-$D7)<0.000001,$E7=$F7),"PASS","CHECK") -> PASS | H7: Aliran melewati toleransi
A8: TC-004 | B8: WO-2404 | C8: 25.013333 | D8: =IFERROR(INDEX('INPUT LOG'!$M$5:$M$54,MATCH($B8,'INPUT LOG'!$A$5:$A$54,0)),"") -> 25.013333 | E8: PASS | F8: =IFERROR(INDEX('INPUT LOG'!$O$5:$O$54,MATCH($B8,'INPUT LOG'!$A$5:$A$54,0)),"") -> PASS | G8: =IF(AND(ABS($C8-$D8)<0.000001,$E8=$F8),"PASS","CHECK") -> PASS | H8: Kaliper masih dalam toleransi
A9: TC-005 | B9: WO-2405 | C9: 10.033333 | D9: =IFERROR(INDEX('INPUT LOG'!$M$5:$M$54,MATCH($B9,'INPUT LOG'!$A$5:$A$54,0)),"") -> 10.033333 | E9: REVIEW | F9: =IFERROR(INDEX('INPUT LOG'!$O$5:$O$54,MATCH($B9,'INPUT LOG'!$A$5:$A$54,0)),"") -> REVIEW | G9: =IF(AND(ABS($C9-$D9)<0.000001,$E9=$F9),"PASS","CHECK") -> PASS | H9: Timbangan melewati toleransi
A12: Syarat penerimaan
A13: Semua baris di kolom Hasil cek harus berstatus PASS. Jika ada perbedaan, catat penyebab dan persetujuannya di CHANGE LOG sebelum file diberikan kepada pengguna untuk UAT.

Sheet CHANGE LOG
A1: CHANGE LOG
A2: Isi satu baris setiap kali struktur, rumus, atau aturan workbook berubah.
A4: Versi | B4: Tanggal | C4: Bagian | D4: Perubahan | E4: Alasan | F4: Persetujuan teknis | G4: Diperiksa oleh | H4: Status
A5: 0.1 | B5: 46291 | C5: Struktur workbook | D5: Memisahkan input, master data, perhitungan, laporan, dan validasi | E5: Membuat contoh kerja | F5: Tidak berlaku, data fiktif | G5: Pemeriksaan mandiri | H5: Selesai
A6: 0.1 | B6: 46291 | C6: Kontrol input | D6: Menambahkan dropdown, batas nilai, warna sel, dan proteksi formula | E6: Mengurangi salah input | F6: Tidak berlaku, data fiktif | G6: Pemeriksaan mandiri | H6: Selesai
A7: 0.1 | B7: 46291 | C7: Perhitungan | D7: Menetapkan aturan contoh: ABS(selisih) <= toleransi | E7: Menguji alur perhitungan | F7: Ganti dengan aturan yang disetujui klien | G7: Pemeriksaan mandiri | H7: Selesai
